<?xml version="1.0"?>
<robot xmlns:xacro="http://wiki.ros.org/xacro">

  <xacro:macro name="quickchanger_grippers" params="parent">
  <xacro:property name="quickchanger_grippers_visual_params" value="${xacro.load_yaml('$(find ur_description)/config/quickchanger_grippers_visual_parameters.yaml')}"/>
  <xacro:property name="sec_mesh_files" value="${quickchanger_grippers_visual_params['mesh_files']}" scope="parent"/>
  <xacro:property name="force_abs_paths" value="true" scope="parent"/>

    <!-- quickchanger_link -->
    <link name="quickchanger_link">
      <visual>
        <origin xyz="0 0 0" rpy="0 0 0"/>
        <geometry>
          <xacro:get_mesh name="quickchanger" type="visual"/>
        </geometry>
        <material name="${sec_mesh_files['quickchanger']['visual']['material']['name']}">
          <color rgba="${sec_mesh_files['quickchanger']['visual']['material']['color']}"/>
        </material>
      </visual>
      <inertial>
        <mass value="2.0"/>
        <origin xyz="0 0 0" rpy="0 0 0"/>
        <inertia ixx="1e-5" ixy="0" ixz="0" iyy="1e-5" iyz="0" izz="1e-5"/>
      </inertial>
    </link>

    <!-- quickchanger_joint -->
    <joint name="quickchanger_joint" type="fixed">
      <parent link="${parent}"/>
      <child link="quickchanger_link"/>
      <!-- adjust quickchanger orientation to match flange orientation -->
      <origin xyz="0 0 0.012" rpy="1.57 3.14 1.57"/>
    </joint>

    <!-- suction_link -->
    <link name="suction_link">
      <visual>
        <origin xyz="0 0 0" rpy="0 0 0"/>
        <geometry>
          <xacro:get_mesh name="suction" type="visual"/>
        </geometry>
        <material name="${sec_mesh_files['suction']['visual']['material']['name']}">
          <color rgba="${sec_mesh_files['suction']['visual']['material']['color']}"/>
        </material>
      </visual>
      <inertial>
        <mass value="1.0"/>
        <origin xyz="0 0 0" rpy="0 0 0"/>
        <inertia ixx="1e-5" ixy="0" ixz="0" iyy="1e-5" iyz="0" izz="1e-5"/>
      </inertial>
    </link>

    <!-- suction_joint -->
    <joint name="suction_joint" type="fixed">
      <parent link="quickchanger_link"/>
      <child link="suction_link"/>
      <origin xyz="0.1208 0.0019 0.1088" rpy="0 0.785 0"/>
    </joint>

    <!-- tooltip_adapter_link -->
    <link name="tooltip_adapter_link">
      <visual>
        <origin xyz="0 0 0" rpy="0 0 0"/>
        <geometry>
          <xacro:get_mesh name="tooltip_adapter" type="visual"/>
        </geometry>
        <material name="${sec_mesh_files['tooltip_adapter']['visual']['material']['name']}">
          <color rgba="${sec_mesh_files['tooltip_adapter']['visual']['material']['color']}"/>
        </material>
      </visual>
      <inertial>
        <mass value="1.0"/>
        <origin xyz="0 0 0" rpy="0 0 0"/>
        <inertia ixx="1e-5" ixy="0" ixz="0" iyy="1e-5" iyz="0" izz="1e-5"/>
      </inertial>
    </link>

    <!-- tooltip_adapter_joint -->
    <joint name="tooltip_adapter_joint" type="fixed">
      <parent link="quickchanger_link"/>
      <child link="tooltip_adapter_link"/>
      <origin xyz="-0.1341 0.053 0.1221" rpy="-0.785 0 1.57"/>
    </joint>

    <!-- tooltip1_link -->
    <link name="tooltip1_link">
      <visual>
        <origin xyz="0 0 0" rpy="0 0 0"/>
        <geometry>
          <xacro:get_mesh name="tooltip1" type="visual"/>
        </geometry>
        <material name="${sec_mesh_files['tooltip1']['visual']['material']['name']}">
          <color rgba="${sec_mesh_files['tooltip1']['visual']['material']['color']}"/>
        </material>
      </visual>
      <inertial>
        <mass value="0.5"/>
        <origin xyz="0 0 0" rpy="0 0 0"/>
        <inertia ixx="0.001" ixy="0" ixz="0" iyy="0.001" iyz="0" izz="0.001"/>
      </inertial>
    </link>

    <!-- tooltip1_joint -->

    <joint name="tooltip1_joint" type="prismatic">
      <parent link="tooltip_adapter_link"/>
      <child link="tooltip1_link"/>
      <origin xyz="-0.002 0 0.04" rpy="0 0 0"/>
      <axis xyz="1 0 0"/>
      <limit lower="-1.0" upper="0.041" effort="50" velocity="10"/>
    </joint>

    <!-- tooltip2 -->
    <link name="tooltip2_link">
      <visual>
        <origin xyz="0 0 0" rpy="0 0 0"/>
        <geometry>
          <xacro:get_mesh name="tooltip2" type="visual"/>
        </geometry>
        <material name="${sec_mesh_files['tooltip2']['visual']['material']['name']}">
          <color rgba="${sec_mesh_files['tooltip2']['visual']['material']['color']}"/>
        </material>
      </visual>
      <inertial>
        <mass value="0.5"/>
        <origin xyz="0 0 0" rpy="0 0 0"/>
        <inertia ixx="0.001" ixy="0" ixz="0" iyy="0.001" iyz="0" izz="0.001"/>
      </inertial>
    </link>

    <joint name="tooltip2_joint" type="prismatic">
      <parent link="tooltip_adapter_link"/>
      <child link="tooltip2_link"/>
      <origin xyz="0.002 0 0.04" rpy="0 0 3.14"/>
      <axis xyz="1 0 0"/>
      <limit lower="-1.0" upper="0.041" effort="50" velocity="10"/>
    </joint>


  </xacro:macro>
</robot>

